/home/cse/dual/cs5190443/scratch/anaconda3/envs/v100/lib/python3.9/site-packages/dateutil/parser/_parser.py:1207: UnknownTimezoneWarning: tzname WIT identified but not understood.  Pass `tzinfos` argument in order to correctly return a timezone-aware datetime.  In a future version, this will raise an exception.
  warnings.warn("tzname {tzname} identified but not understood.  "
/home/cse/dual/cs5190443/scratch/anaconda3/envs/v100/lib/python3.9/site-packages/dateutil/parser/_parser.py:1207: UnknownTimezoneWarning: tzname ET identified but not understood.  Pass `tzinfos` argument in order to correctly return a timezone-aware datetime.  In a future version, this will raise an exception.
  warnings.warn("tzname {tzname} identified but not understood.  "
/home/cse/dual/cs5190443/scratch/anaconda3/envs/v100/lib/python3.9/site-packages/dateutil/parser/_parser.py:1207: UnknownTimezoneWarning: tzname M identified but not understood.  Pass `tzinfos` argument in order to correctly return a timezone-aware datetime.  In a future version, this will raise an exception.
  warnings.warn("tzname {tzname} identified but not understood.  "
/home/cse/dual/cs5190443/scratch/anaconda3/envs/v100/lib/python3.9/site-packages/dateutil/parser/_parser.py:1207: UnknownTimezoneWarning: tzname CDT identified but not understood.  Pass `tzinfos` argument in order to correctly return a timezone-aware datetime.  In a future version, this will raise an exception.
  warnings.warn("tzname {tzname} identified but not understood.  "
/home/cse/dual/cs5190443/scratch/anaconda3/envs/v100/lib/python3.9/site-packages/dateutil/parser/_parser.py:1207: UnknownTimezoneWarning: tzname WIT identified but not understood.  Pass `tzinfos` argument in order to correctly return a timezone-aware datetime.  In a future version, this will raise an exception.
  warnings.warn("tzname {tzname} identified but not understood.  "
/home/cse/dual/cs5190443/scratch/anaconda3/envs/v100/lib/python3.9/site-packages/dateutil/parser/_parser.py:1207: UnknownTimezoneWarning: tzname ET identified but not understood.  Pass `tzinfos` argument in order to correctly return a timezone-aware datetime.  In a future version, this will raise an exception.
  warnings.warn("tzname {tzname} identified but not understood.  "
/home/cse/dual/cs5190443/scratch/anaconda3/envs/v100/lib/python3.9/site-packages/dateutil/parser/_parser.py:1207: UnknownTimezoneWarning: tzname CST identified but not understood.  Pass `tzinfos` argument in order to correctly return a timezone-aware datetime.  In a future version, this will raise an exception.
  warnings.warn("tzname {tzname} identified but not understood.  "
/home/cse/dual/cs5190443/scratch/anaconda3/envs/v100/lib/python3.9/site-packages/dateutil/parser/_parser.py:1207: UnknownTimezoneWarning: tzname EDT identified but not understood.  Pass `tzinfos` argument in order to correctly return a timezone-aware datetime.  In a future version, this will raise an exception.
  warnings.warn("tzname {tzname} identified but not understood.  "
/home/cse/dual/cs5190443/scratch/anaconda3/envs/v100/lib/python3.9/site-packages/dateutil/parser/_parser.py:1207: UnknownTimezoneWarning: tzname EST identified but not understood.  Pass `tzinfos` argument in order to correctly return a timezone-aware datetime.  In a future version, this will raise an exception.
  warnings.warn("tzname {tzname} identified but not understood.  "
/home/cse/dual/cs5190443/scratch/anaconda3/envs/v100/lib/python3.9/site-packages/dateutil/parser/_parser.py:1207: UnknownTimezoneWarning: tzname CET identified but not understood.  Pass `tzinfos` argument in order to correctly return a timezone-aware datetime.  In a future version, this will raise an exception.
  warnings.warn("tzname {tzname} identified but not understood.  "
Traceback (most recent call last):
  File "/scratch/cse/dual/cs5190443/col772-2302/A2_eval/COL772-2302-A2/cs1210549/table_model.py", line 507, in <module>
    create_and_train(train_file, val_file)
  File "/scratch/cse/dual/cs5190443/col772-2302/A2_eval/COL772-2302-A2/cs1210549/table_model.py", line 461, in create_and_train
    model.row_train(train_dataloader, 15, 32, val_dataloader)
  File "/scratch/cse/dual/cs5190443/col772-2302/A2_eval/COL772-2302-A2/cs1210549/table_model.py", line 345, in row_train
    (questions, columns, rows, col_labels, row_labels) = train_dataloader.get_next_items(batch_size, neg_sampling=True)
  File "/scratch/cse/dual/cs5190443/col772-2302/A2_eval/COL772-2302-A2/cs1210549/table_model.py", line 156, in get_next_items
    neg_samples = np.random.choice([i for i in range(len(self.row_data[i])) if i not in positive_samples], neg_no, replace=False)
  File "numpy/random/mtrand.pyx", line 1004, in numpy.random.mtrand.RandomState.choice
ValueError: Negative dimensions are not allowed
Traceback (most recent call last):
  File "/scratch/cse/dual/cs5190443/col772-2302/A2_eval/COL772-2302-A2/cs1210549/table_model.py", line 513, in <module>
    test_model(test_file, output_file)
  File "/scratch/cse/dual/cs5190443/col772-2302/A2_eval/COL772-2302-A2/cs1210549/table_model.py", line 483, in test_model
    model.load_state_dict(T.load('final.model'))
  File "/home/cse/dual/cs5190443/scratch/anaconda3/envs/v100/lib/python3.9/site-packages/torch/serialization.py", line 998, in load
    with _open_file_like(f, 'rb') as opened_file:
  File "/home/cse/dual/cs5190443/scratch/anaconda3/envs/v100/lib/python3.9/site-packages/torch/serialization.py", line 445, in _open_file_like
    return _open_file(name_or_buffer, mode)
  File "/home/cse/dual/cs5190443/scratch/anaconda3/envs/v100/lib/python3.9/site-packages/torch/serialization.py", line 426, in __init__
    super().__init__(open(name, mode))
FileNotFoundError: [Errno 2] No such file or directory: 'final.model'
Traceback (most recent call last):
  File "/scratch/cse/dual/cs5190443/col772-2302/A2_eval/COL772-2302-A2/evaluate_submission.py", line 12, in <module>
    sub_file = [json.loads(x) for x in open(submission_file)]
FileNotFoundError: [Errno 2] No such file or directory: 'cs1210549/predictions_new.jsonl'
