[nltk_data] Error loading punkt: <urlopen error Remote end closed
[nltk_data]     connection without response>
/scratch/cse/dual/cs5190443/col772-2302/A2_eval/COL772-2302-A2_resub/ee1210984/train.py:100: UserWarning: Creating a tensor from a list of numpy.ndarrays is extremely slow. Please consider converting the list to a single numpy.ndarray with numpy.array() before converting to a tensor. (Triggered internally at ../torch/csrc/utils/tensor_new.cpp:275.)
  self.questions.append(torch.tensor(questions, dtype=torch.float32))
/home/cse/dual/cs5190443/scratch/anaconda3/envs/v100/lib/python3.9/site-packages/torch/nested/__init__.py:166: UserWarning: The PyTorch API of nested tensors is in prototype stage and will change in the near future. (Triggered internally at ../aten/src/ATen/NestedTensorImpl.cpp:177.)
  return _nested.nested_tensor(
Traceback (most recent call last):
  File "/scratch/cse/dual/cs5190443/col772-2302/A2_eval/COL772-2302-A2_resub/ee1210984/train.py", line 230, in <module>
    main()
  File "/scratch/cse/dual/cs5190443/col772-2302/A2_eval/COL772-2302-A2_resub/ee1210984/train.py", line 207, in main
    col_num=col_num.to(device)
AttributeError: 'list' object has no attribute 'to'
[nltk_data] Error loading punkt: <urlopen error Remote end closed
[nltk_data]     connection without response>
/scratch/cse/dual/cs5190443/col772-2302/A2_eval/COL772-2302-A2_resub/ee1210984/test.py:85: UserWarning: Creating a tensor from a list of numpy.ndarrays is extremely slow. Please consider converting the list to a single numpy.ndarray with numpy.array() before converting to a tensor. (Triggered internally at ../torch/csrc/utils/tensor_new.cpp:275.)
  self.questions.append(torch.tensor(questions, dtype=torch.float32))
Traceback (most recent call last):
  File "/scratch/cse/dual/cs5190443/col772-2302/A2_eval/COL772-2302-A2_resub/ee1210984/test.py", line 248, in <module>
    main()
  File "/scratch/cse/dual/cs5190443/col772-2302/A2_eval/COL772-2302-A2_resub/ee1210984/test.py", line 245, in main
    run_inference(args.test_file, args.pred_file)
  File "/scratch/cse/dual/cs5190443/col772-2302/A2_eval/COL772-2302-A2_resub/ee1210984/test.py", line 180, in run_inference
    model.load_state_dict(torch.load('model.pth', map_location=device))
  File "/home/cse/dual/cs5190443/scratch/anaconda3/envs/v100/lib/python3.9/site-packages/torch/serialization.py", line 998, in load
    with _open_file_like(f, 'rb') as opened_file:
  File "/home/cse/dual/cs5190443/scratch/anaconda3/envs/v100/lib/python3.9/site-packages/torch/serialization.py", line 445, in _open_file_like
    return _open_file(name_or_buffer, mode)
  File "/home/cse/dual/cs5190443/scratch/anaconda3/envs/v100/lib/python3.9/site-packages/torch/serialization.py", line 426, in __init__
    super().__init__(open(name, mode))
FileNotFoundError: [Errno 2] No such file or directory: 'model.pth'
Traceback (most recent call last):
  File "/scratch/cse/dual/cs5190443/col772-2302/A2_eval/COL772-2302-A2_resub/evaluate_submission.py", line 12, in <module>
    sub_file = [json.loads(x) for x in open(submission_file)]
FileNotFoundError: [Errno 2] No such file or directory: 'ee1210984/predictions_new.jsonl'
