[nltk_data] Error loading punkt: <urlopen error Remote end closed
[nltk_data]     connection without response>
[nltk_data] Error loading punkt: <urlopen error Remote end closed
[nltk_data]     connection without response>
Traceback (most recent call last):
  File "/scratch/cse/dual/cs5190443/col772-2302/A2_eval/COL772-2302-A2_resub/mt1200858/test_model.py", line 252, in <module>
    actual_tester(test_file_path,model)
  File "/scratch/cse/dual/cs5190443/col772-2302/A2_eval/COL772-2302-A2_resub/mt1200858/test_model.py", line 194, in actual_tester
    per_row_list.append(val_table_rows[i][j][predicted_col_index[i]])
IndexError: list index out of range
Traceback (most recent call last):
  File "/scratch/cse/dual/cs5190443/col772-2302/A2_eval/COL772-2302-A2_resub/evaluate_submission.py", line 12, in <module>
    sub_file = [json.loads(x) for x in open(submission_file)]
FileNotFoundError: [Errno 2] No such file or directory: 'mt1200858/predictions_new.jsonl'
